Workbook

Sheet Lista Itemów
A1: Nazwa | B1: Opis | C1: Main Flaga | D1: Flaga | E1: ItemCategory | F1: ItemType | G1: ItemGroupType | H1: PLIK | I1: Stackowanie | J1: Instancja[OLD] | K1: Instancja [SAGA3] | L1: model nazwa | M1: Waga | N1: hideNick | O1: Liczba użyć | P1: Stamina 1 Hit | Q1: HP 1 hit | R1: Mana 1 Hit | S1: Stamina | T1: HP | U1: MANA | V1: Rodzaj Obrażeń | W1: DMG | X1: Zasięg | Y1: W: Siła | Z1: W: Zręczność | AA1: W: Inteligencja | AB1: W: Krąg | AC1: W: Mana | AD1: Wytrzymałość | AE1: expirationTime | AF1: Obuchowa | AG1: Pociski | AH1: Sieczna | AI1: Magia | AJ1: Ogień | AK1: Upadek | AL1: Tier | AM1: Profesja | AN1: Kategoria
A2: Pieczona ryba | B2: Zwykła pieczona ryba | C2: ITEM_CAT_FOOD | D2: - | E2: Consumable | F2: Food | G2: AdminFood | H2: consumable | I2: TRUE | J2: ITFO_FISH | K2: ITFO_GS_01 | L2: ItFo_Fish.3ds | M2: 0.3 | N2: FALSE | O2: 2 | P2: 2.5 | Q2: 0 | R2: 0 | S2: =O2*P2 -> 5 | T2: =O2*Q2 -> 0 | U2: =O2*R2 -> 0 | V2: BRAK | W2: BRAK | X2: BRAK | Y2: BRAK | Z2: BRAK | AA2: BRAK | AB2: BRAK | AC2: BRAK | AD2: BRAK | AE2: 10800 | AF2: BRAK | AG2: BRAK | AH2: BRAK | AI2: BRAK | AJ2: BRAK | AK2: BRAK | AL2: T0 | AM2: Kucharz | AN2: Kuchenka
A3: Pieczone mięso | B3: Zwykłe pieczone mięso | C3: ITEM_CAT_FOOD | D3: - | E3: Consumable | F3: Food | G3: AdminFood | H3: consumable | I3: TRUE | J3: ITFO_ROASTEDRATMEAT | K3: ITFO_GS_02 | L3: KM_cooked_meat_02.3ds | M3: 0.3 | N3: FALSE | O3: 2 | P3: 2.5 | Q3: 0 | R3: 0 | S3: =O3*P3 -> 5 | T3: =O3*Q3 -> 0 | U3: =O3*R3 -> 0 | V3: BRAK | W3: BRAK | X3: BRAK | Y3: BRAK | Z3: BRAK | AA3: BRAK | AB3: BRAK | AC3: BRAK | AD3: BRAK | AE3: 10800 | AF3: BRAK | AG3: BRAK | AH3: BRAK | AI3: BRAK | AJ3: BRAK | AK3: BRAK | AL3: T0 | AM3: Kucharz | AN3: Kuchenka
A4: Pieczony chwast | B4: Wysuszone i upieczone liście ziela. | C4: ITEM_CAT_FOOD | D4: - | E4: Consumable | F4: Food | G4: AdminFood | H4: consumable | I4: TRUE | J4: ITPL_WEED | K4: ITFO_GS_03 | L4: ItPl_Weed.3ds | M4: 0.3 | N4: FALSE | O4: 1 | P4: 5 | Q4: 0 | R4: 0 | S4: 5 | T4: 0 | U4: 0 | V4: BRAK | W4: BRAK | X4: BRAK | Y4: BRAK | Z4: BRAK | AA4: BRAK | AB4: BRAK | AC4: BRAK | AD4: BRAK | AE4: 43200 | AF4: BRAK | AG4: BRAK | AH4: BRAK | AI4: BRAK | AJ4: BRAK | AK4: BRAK | AL4: T0 | AM4: Kucharz | AN4: Kuchenka
A5: Pasztet z resztek | B5: Idealny sposób, by dać drugie życie temu, co zostało. | C5: ITEM_CAT_FOOD | D5: - | E5: Consumable | F5: Food | G5: AdminFood | H5: consumable | I5: TRUE | J5: ITFO_POORPATE | K5: ITFO_GS_03 | L5: KM_ITFO_oatmeal.3ds | M5: 0.3 | N5: FALSE | O5: 4 | P5: 2.5 | Q5: 0 | R5: 0 | S5: =O5*P5 -> 10 | T5: =O5*Q5 -> 0 | U5: =O5*R5 -> 0 | V5: BRAK | W5: BRAK | X5: BRAK | Y5: BRAK | Z5: BRAK | AA5: BRAK | AB5: BRAK | AC5: BRAK | AD5: BRAK | AE5: 10800 | AF5: BRAK | AG5: BRAK | AH5: BRAK | AI5: BRAK | AJ5: BRAK | AK5: BRAK | AL5: T0 | AM5: Kucharz | AN5: Kuchenka
A6: Pieczone owady | B6: Chrupiemy jak królestwo owadów, no bo czemu nie? | C6: ITEM_CAT_FOOD | D6: - | E6: Consumable | F6: Food | G6: AdminFood | H6: consumable | I6: TRUE | J6: ITFO_ROASTEDINSECTS | K6: ITFO_GS_04 | L6: KM_ITFO_meatbug.3ds | M6: 0.3 | N6: FALSE | O6: 2 | P6: 5 | Q6: 0 | R6: 0 | S6: =O6*P6 -> 10 | T6: =O6*Q6 -> 0 | U6: =O6*R6 -> 0 | V6: BRAK | W6: BRAK | X6: BRAK | Y6: BRAK | Z6: BRAK | AA6: BRAK | AB6: BRAK | AC6: BRAK | AD6: BRAK | AE6: 10800 | AF6: BRAK | AG6: BRAK | AH6: BRAK | AI6: BRAK | AJ6: BRAK | AK6: BRAK | AL6: T0 | AM6: Kucharz | AN6: Kuchenka
A7: Chrupkie łuski rybne | B7: Jeśli ryba ma skórę, to czemu nie wziąć jej do pieca? | C7: ITEM_CAT_FOOD | D7: - | E7: Consumable | F7: Food | G7: AdminFood | H7: consumable | I7: TRUE | J7: ITFO_FRIEDFISHSKINS | K7: ITFO_GS_05 | L7: ItFo_FriedFishSkins.3ds | M7: 0.3 | N7: FALSE | O7: 1 | P7: 10 | Q7: 0 | R7: 0 | S7: =O7*P7 -> 10 | T7: =O7*Q7 -> 0 | U7: =O7*R7 -> 0 | V7: BRAK | W7: BRAK | X7: BRAK | Y7: BRAK | Z7: BRAK | AA7: BRAK | AB7: BRAK | AC7: BRAK | AD7: BRAK | AE7: 10800 | AF7: BRAK | AG7: BRAK | AH7: BRAK | AI7: BRAK | AJ7: BRAK | AK7: BRAK | AL7: T0 | AM7: Kucharz | AN7: Kuchenka
A8: Wiejska jajecznica | B8: Prosta, jak życie na wsi, ale smak ma wyjątkowy! | C8: ITEM_CAT_FOOD | D8: - | E8: Consumable | F8: Food | G8: AdminFood | H8: consumable | I8: TRUE | J8: ITFO_POOREGGS | K8: ITFO_GS_06 | L8: KM_ITFO_ScrambledEggs.3ds | M8: 0.4 | N8: FALSE | O8: 4 | P8: 5 | Q8: 0 | R8: 0 | S8: =O8*P8 -> 20 | T8: =O8*Q8 -> 0 | U8: =O8*R8 -> 0 | V8: BRAK | W8: BRAK | X8: BRAK | Y8: BRAK | Z8: BRAK | AA8: BRAK | AB8: BRAK | AC8: BRAK | AD8: BRAK | AE8: 10800 | AF8: BRAK | AG8: BRAK | AH8: BRAK | AI8: BRAK | AJ8: BRAK | AK8: BRAK | AL8: T1 | AM8: Kucharz | AN8: Kuchenka
A9: =HYPERLINK("https://imgur.com/eJ3CxWA","Szczur na patyku") -> Szczur na patyku | B9: Bo czasem egzotyczne smaki to najlepsza przygoda! | C9: ITEM_CAT_FOOD | D9: - | E9: Consumable | F9: Food | G9: AdminFood | H9: consumable | I9: TRUE | J9: ITFO_RATSTICK | K9: ITFO_GS_07 | L9: KM_ITFO_shashlik.3ds | M9: 0.4 | N9: FALSE | O9: 2 | P9: 7.5 | Q9: 0 | R9: 0 | S9: =O9*P9 -> 15 | T9: =O9*Q9 -> 0 | U9: =O9*R9 -> 0 | V9: BRAK | W9: BRAK | X9: BRAK | Y9: BRAK | Z9: BRAK | AA9: BRAK | AB9: BRAK | AC9: BRAK | AD9: BRAK | AE9: 10800 | AF9: BRAK | AG9: BRAK | AH9: BRAK | AI9: BRAK | AJ9: BRAK | AK9: BRAK | AL9: T1 | AM9: Kucharz | AN9: Kuchenka
A10: Ryba w cieście piwnym | B10: Smażona ryba, z odrobiną złocistego piwa – idealna równowaga! | C10: ITEM_CAT_FOOD | D10: - | E10: Consumable | F10: Food | G10: AdminFood | H10: consumable | I10: TRUE | J10: ITFO_BEERFISH | K10: ITFO_GS_08 | L10: ItFo_BeerFish.3ds | M10: 0.4 | N10: FALSE | O10: 2 | P10: 10 | Q10: 0 | R10: 0 | S10: =O10*P10 -> 20 | T10: =O10*Q10 -> 0 | U10: =O10*R10 -> 0 | V10: BRAK | W10: BRAK | X10: BRAK | Y10: BRAK | Z10: BRAK | AA10: BRAK | AB10: BRAK | AC10: BRAK | AD10: BRAK | AE10: 10800 | AF10: BRAK | AG10: BRAK | AH10: BRAK | AI10: BRAK | AJ10: BRAK | AK10: BRAK | AL10: T1 | AM10: Kucharz | AN10: Kuchenka
A11: Bigos z ochłapów | B11: Gdy mięso wędruje w towarzystwie kapusty na wesele smaku! | C11: ITEM_CAT_FOOD | D11: - | E11: Consumable | F11: Food | G11: AdminFood | H11: consumable | I11: TRUE | J11: ITFO_MEATMISHMASH | K11: ITFO_GS_09 | L11: ITFO_STEW_02.3ds | M11: 0.4 | N11: FALSE | O11: 4 | P11: 5 | Q11: 0 | R11: 0 | S11: =O11*P11 -> 20 | T11: =O11*Q11 -> 0 | U11: =O11*R11 -> 0 | V11: BRAK | W11: BRAK | X11: BRAK | Y11: BRAK | Z11: BRAK | AA11: BRAK | AB11: BRAK | AC11: BRAK | AD11: BRAK | AE11: 10800 | AF11: BRAK | AG11: BRAK | AH11: BRAK | AI11: BRAK | AJ11: BRAK | AK11: BRAK | AL11: T1 | AM11: Kucharz | AN11: Kuchenka
A12: Kiszone grzyby | B12: Grzybki, które tak szybko nie zapomną, jak się kisiły! | C12: ITEM_CAT_FOOD | D12: - | E12: Consumable | F12: Food | G12: AdminFood | H12: consumable | I12: TRUE | J12: ITFO_PICKLEDMUSHROOMS | K12: ITFO_GS_10 | L12: KM_ITFO_mushrooms.3ds | M12: 0.4 | N12: FALSE | O12: 2 | P12: 5 | Q12: 0 | R12: 0 | S12: =O12*P12 -> 10 | T12: =O12*Q12 -> 0 | U12: =O12*R12 -> 0 | V12: BRAK | W12: BRAK | X12: BRAK | Y12: BRAK | Z12: BRAK | AA12: BRAK | AB12: BRAK | AC12: BRAK | AD12: BRAK | AE12: 10800 | AF12: BRAK | AG12: BRAK | AH12: BRAK | AI12: BRAK | AJ12: BRAK | AK12: BRAK | AL12: T1 | AM12: Kucharz | AN12: Kuchenka
A13: Kwaśna rzepa | B13: Właśnie odkrywasz nowy sposób, by pokochać rzepę! | C13: ITEM_CAT_FOOD | D13: - | E13: Consumable | F13: Food | G13: AdminFood | H13: consumable | I13: TRUE | J13: ITFO_PICKLEDBEET | K13: ITFO_GS_11 | L13: KM_ITFO_PickledTurnips.3ds | M13: 0.4 | N13: FALSE | O13: 4 | P13: 2.5 | Q13: 0 | R13: 0 | S13: =O13*P13 -> 10 | T13: =O13*Q13 -> 0 | U13: =O13*R13 -> 0 | V13: BRAK | W13: BRAK | X13: BRAK | Y13: BRAK | Z13: BRAK | AA13: BRAK | AB13: BRAK | AC13: BRAK | AD13: BRAK | AE13: 10800 | AF13: BRAK | AG13: BRAK | AH13: BRAK | AI13: BRAK | AJ13: BRAK | AK13: BRAK | AL13: T1 | AM13: Kucharz | AN13: Kuchenka
A14: Szaszłyk ze ścierwojada i dyni | B14: A na grillu zawsze coś nowego do spróbowania! | C14: ITEM_CAT_FOOD | D14: - | E14: Consumable | F14: Food | G14: AdminFood | H14: consumable | I14: TRUE | J14: ITFO_RATSTICK | K14: ITFO_GS_12 | L14: KM_ITFO_shashlik.3ds | M14: 0.5 | N14: FALSE | O14: 5 | P14: 5 | Q14: 0 | R14: 0 | S14: =O14*P14 -> 25 | T14: =O14*Q14 -> 0 | U14: =O14*R14 -> 0 | V14: BRAK | W14: BRAK | X14: BRAK | Y14: BRAK | Z14: BRAK | AA14: BRAK | AB14: BRAK | AC14: BRAK | AD14: BRAK | AE14: 10800 | AF14: BRAK | AG14: BRAK | AH14: BRAK | AI14: BRAK | AJ14: BRAK | AK14: BRAK | AL14: T2 | AM14: Kucharz | AN14: Kuchenka
A15: Ryba w occie z ognistym zielem | B15: Gdzie kwaśno, gorąco, i jeszcze gorzej! (Ale smacznie) | C15: ITEM_CAT_FOOD | D15: - | E15: Consumable | F15: Food | G15: AdminFood | H15: consumable | I15: TRUE | J15: ITFO_FISHVINEGAR | K15: ITFO_GS_13 | L15: ItFo_FishSoup.3ds | M15: 0.5 | N15: FALSE | O15: 2 | P15: 12.5 | Q15: 0 | R15: 0 | S15: =O15*P15 -> 25 | T15: =O15*Q15 -> 0 | U15: =O15*R15 -> 0 | V15: BRAK | W15: BRAK | X15: BRAK | Y15: BRAK | Z15: BRAK | AA15: BRAK | AB15: BRAK | AC15: BRAK | AD15: BRAK | AE15: 10800 | AF15: BRAK | AG15: BRAK | AH15: BRAK | AI15: BRAK | AJ15: BRAK | AK15: BRAK | AL15: T2 | AM15: Kucharz | AN15: Kuchenka
A16: Wędzona ryba ziołowa | B16: Dym i zioła – jak szef kuchni w lesie! | C16: ITEM_CAT_FOOD | D16: - | E16: Consumable | F16: Food | G16: AdminFood | H16: consumable | I16: TRUE | J16: ITFO_SMOKEDHERBFISH | K16: ITFO_GS_14 | L16: KM_ITFO_Fish01.3ds | M16: 0.5 | N16: FALSE | O16: 1 | P16: 25 | Q16: 0 | R16: 0 | S16: =O16*P16 -> 25 | T16: =O16*Q16 -> 0 | U16: =O16*R16 -> 0 | V16: BRAK | W16: BRAK | X16: BRAK | Y16: BRAK | Z16: BRAK | AA16: BRAK | AB16: BRAK | AC16: BRAK | AD16: BRAK | AE16: 10800 | AF16: BRAK | AG16: BRAK | AH16: BRAK | AI16: BRAK | AJ16: BRAK | AK16: BRAK | AL16: T2 | AM16: Kucharz | AN16: Kuchenka
A17: Garnek mięsny | B17: Gar, który ma więcej tłuszczu niż twoje plany na dietę. | C17: ITEM_CAT_FOOD | D17: - | E17: Consumable | F17: Food | G17: AdminFood | H17: consumable | I17: TRUE | J17: ITFO_MARTHSOUP3 | K17: ITFO_GS_15 | L17: KM_ITFO_FoodPot.3ds | M17: 0.5 | N17: FALSE | O17: 1 | P17: 25 | Q17: 0 | R17: 0 | S17: =O17*P17 -> 25 | T17: =O17*Q17 -> 0 | U17: =O17*R17 -> 0 | V17: BRAK | W17: BRAK | X17: BRAK | Y17: BRAK | Z17: BRAK | AA17: BRAK | AB17: BRAK | AC17: BRAK | AD17: BRAK | AE17: 10800 | AF17: BRAK | AG17: BRAK | AH17: BRAK | AI17: BRAK | AJ17: BRAK | AK17: BRAK | AL17: T2 | AM17: Kucharz | AN17: Kuchenka
A18: Pieczone ostrygi | B18: Na szybko, i na ostro! | C18: ITEM_CAT_FOOD | D18: - | E18: Consumable | F18: Food | G18: AdminFood | H18: consumable | I18: TRUE | J18: ITFO_SIMPLEOYSTERS | K18: ITFO_GS_16 | L18: KM_ITFO_SeaFruit.3ds | M18: 0.5 | N18: FALSE | O18: 2 | P18: 12.5 | Q18: 0 | R18: 0 | S18: =O18*P18 -> 25 | T18: =O18*Q18 -> 0 | U18: =O18*R18 -> 0 | V18: BRAK | W18: BRAK | X18: BRAK | Y18: BRAK | Z18: BRAK | AA18: BRAK | AB18: BRAK | AC18: BRAK | AD18: BRAK | AE18: 10800 | AF18: BRAK | AG18: BRAK | AH18: BRAK | AI18: BRAK | AJ18: BRAK | AK18: BRAK | AL18: T2 | AM18: Kucharz | AN18: Kuchenka
A19: Mięsne paczuszki | B19: W środku niespodzianka: mięso! A na zewnątrz chrupiąca przyjemność. | C19: ITEM_CAT_FOOD | D19: - | E19: Consumable | F19: Food | G19: AdminFood | H19: consumable | I19: TRUE | J19: ITFO_MEATPACKS | K19: ITFO_GS_17 | L19: KM_ITFO_BreadMeatVegies.3ds | M19: 0.5 | N19: FALSE | O19: 1 | P19: 25 | Q19: 0 | R19: 0 | S19: =O19*P19 -> 25 | T19: =O19*Q19 -> 0 | U19: =O19*R19 -> 0 | V19: BRAK | W19: BRAK | X19: BRAK | Y19: BRAK | Z19: BRAK | AA19: BRAK | AB19: BRAK | AC19: BRAK | AD19: BRAK | AE19: 10800 | AF19: BRAK | AG19: BRAK | AH19: BRAK | AI19: BRAK | AJ19: BRAK | AK19: BRAK | AL19: T2 | AM19: Kucharz | AN19: Kuchenka
A20: Zapiekanka farmerska | B20: Mieszanka wszystkiego, co rośnie na farmie, i co można zapiec. | C20: ITEM_CAT_FOOD | D20: - | E20: Consumable | F20: Food | G20: AdminFood | H20: consumable | I20: TRUE | J20: ITFO_MEATANDCHEESE | K20: ITFO_GS_18 | L20: ItFo_MeatAndBread.3ds | M20: 0.6 | N20: FALSE | O20: 5 | P20: 7 | Q20: 0 | R20: 0 | S20: =O20*P20 -> 35 | T20: =O20*Q20 -> 0 | U20: =O20*R20 -> 0 | V20: BRAK | W20: BRAK | X20: BRAK | Y20: BRAK | Z20: BRAK | AA20: BRAK | AB20: BRAK | AC20: BRAK | AD20: BRAK | AE20: 14400 | AF20: BRAK | AG20: BRAK | AH20: BRAK | AI20: BRAK | AJ20: BRAK | AK20: BRAK | AL20: T3 | AM20: Kucharz | AN20: Kuchenka
A21: Pieczeń pasterska w miodzie | B21: Pasterski przysmak, który zasługuje na złote medale. | C21: ITEM_CAT_FOOD | D21: - | E21: Consumable | F21: Food | G21: AdminFood | H21: consumable | I21: TRUE | J21: ITFO_SHEPARDROAST | K21: ITFO_GS_19 | L21: ItFo_ShepardRoast.3ds | M21: 0.6 | N21: FALSE | O21: 2 | P21: 17.5 | Q21: 0 | R21: 0 | S21: =O21*P21 -> 35 | T21: =O21*Q21 -> 0 | U21: =O21*R21 -> 0 | V21: BRAK | W21: BRAK | X21: BRAK | Y21: BRAK | Z21: BRAK | AA21: BRAK | AB21: BRAK | AC21: BRAK | AD21: BRAK | AE21: 14400 | AF21: BRAK | AG21: BRAK | AH21: BRAK | AI21: BRAK | AJ21: BRAK | AK21: BRAK | AL21: T3 | AM21: Kucharz | AN21: Kuchenka
... A48: Drożówka cynamonowa | B48: Cynamonowy zapach, który czujesz z kilometra! | C48: ITEM_CAT_FOOD | D48: - | E48: Consumable | F48: Food | G48: AdminFood | H48: consumable | I48: TRUE | J48: ITFO_POORAPPLEPIE | K48: ITFO_GS_46 | L48: KM_ITFO_Pie01.3ds | M48: 0.6 | N48: FALSE | O48: 2 | P48: 17.5 | Q48: 0 | R48: 0 | S48: =O48*P48 -> 35 | T48: =O48*Q48 -> 0 | U48: =O48*R48 -> 0 | V48: BRAK | W48: BRAK | X48: BRAK | Y48: BRAK | Z48: BRAK | AA48: BRAK | AB48: BRAK | AC48: BRAK | AD48: BRAK | AE48: 14400 | AF48: BRAK | AG48: BRAK | AH48: BRAK | AI48: BRAK | AJ48: BRAK | AK48: BRAK | AL48: T3 | AM48: Kucharz | AN48: Piec
A49: Rzepa | B49: Popularne warzywo, do dodania do zup i potraw | C49: ITEM_CAT_FOOD | D49: - | E49: Consumable | F49: Food | G49: AdminFood | H49: consumable | I49: TRUE | J49: ITPL_BEET | K49: ITFO_GS_47 | L49: ItPl_Beet.3ds | M49: 0.3 | N49: FALSE | O49: 1 | P49: 1 | Q49: 0 | R49: 0 | S49: =O49*P49 -> 1 | T49: =O49*Q49 -> 0 | U49: =O49*R49 -> 0 | V49: BRAK | W49: BRAK | X49: BRAK | Y49: BRAK | Z49: BRAK | AA49: BRAK | AB49: BRAK | AC49: BRAK | AD49: BRAK | AE49: 21600 | AF49: BRAK | AG49: BRAK | AH49: BRAK | AI49: BRAK | AJ49: BRAK | AK49: BRAK | AL49: BRAK | AM49: Rolnik
A50: Marchew | B50: Słodkie i soczyste, idealne do dodania smaku potrawom. | C50: ITEM_CAT_FOOD | D50: - | E50: Consumable | F50: Food | G50: AdminFood | H50: consumable | I50: TRUE | J50: itfo_SDRP_food_21 | K50: ITFO_GS_48 | L50: ITFO_CARROT.3ds | M50: 0.3 | N50: FALSE | O50: 1 | P50: 1 | Q50: 0 | R50: 0 | S50: =O50*P50 -> 1 | T50: =O50*Q50 -> 0 | U50: =O50*R50 -> 0 | V50: BRAK | W50: BRAK | X50: BRAK | Y50: BRAK | Z50: BRAK | AA50: BRAK | AB50: BRAK | AC50: BRAK | AD50: BRAK | AE50: 21600 | AF50: BRAK | AG50: BRAK | AH50: BRAK | AI50: BRAK | AJ50: BRAK | AK50: BRAK | AL50: BRAK | AM50: Rolnik
A51: Len | B51: Używany do wytwarzania tkanin, z których można szyć ubrania | C51: ITEM_CAT_NONE | D51: - | E51: Materials | F51: Materials | G51: AdminMaterials | H51: materials | I51: TRUE | J51: GS_NATURE_FLAX_03_GALI | K51: ITMI_GS_MAT_03 | L51: GS_NATURE_FLAX_03_GALI.3ds | M51: 0.3 | N51: FALSE | O51: BRAK | P51: BRAK | Q51: BRAK | R51: BRAK | S51: BRAK | T51: BRAK | U51: BRAK | V51: BRAK | W51: BRAK | X51: BRAK | Y51: BRAK | Z51: BRAK | AA51: BRAK | AB51: BRAK | AC51: BRAK | AD51: BRAK | AE51: 21600 | AF51: BRAK | AG51: BRAK | AH51: BRAK | AI51: BRAK | AJ51: BRAK | AK51: BRAK | AL51: BRAK | AM51: Rolnik
A52: Pszenica | B52: Podstawowy składnik mąki. | C52: ITEM_CAT_NONE | D52: - | E52: Materials | F52: Materials | G52: AdminMaterials | H52: materials | I52: TRUE | J52: GS_NATURE_WHEAT_03_GALI | K52: ITMI_GS_MAT_04 | L52: GS_NATURE_WHEAT_03_GALI.3ds | M52: 0.3 | N52: FALSE | O52: BRAK | P52: BRAK | Q52: BRAK | R52: BRAK | S52: BRAK | T52: BRAK | U52: BRAK | V52: BRAK | W52: BRAK | X52: BRAK | Y52: BRAK | Z52: BRAK | AA52: BRAK | AB52: BRAK | AC52: BRAK | AD52: BRAK | AE52: 21600 | AF52: BRAK | AG52: BRAK | AH52: BRAK | AI52: BRAK | AJ52: BRAK | AK52: BRAK | AL52: BRAK | AM52: Rolnik
A53: Dynia | B53: Słodka i sycąca, idealna do zup, ciast i deserów. | C53: ITEM_CAT_FOOD | D53: - | E53: Consumable | F53: Food | G53: AdminFood | H53: consumable | I53: TRUE | J53: ITFO_SDRP_KM_09 | K53: ITFO_GS_49 | L53: KM_vob_pumpkin_01.3ds | M53: 0.6 | N53: FALSE | O53: 2 | P53: 1 | Q53: 0 | R53: 0 | S53: =O53*P53 -> 2 | T53: =O53*Q53 -> 0 | U53: =O53*R53 -> 0 | V53: BRAK | W53: BRAK | X53: BRAK | Y53: BRAK | Z53: BRAK | AA53: BRAK | AB53: BRAK | AC53: BRAK | AD53: BRAK | AE53: 21600 | AF53: BRAK | AG53: BRAK | AH53: BRAK | AI53: BRAK | AJ53: BRAK | AK53: BRAK | AL53: BRAK | AM53: Rolnik
A54: Kapusta | B54: Niezastąpiony składnik wielu sałatek. | C54: ITEM_CAT_FOOD | D54: - | E54: Consumable | F54: Food | G54: AdminFood | H54: consumable | I54: TRUE | J54: ITFO_GS_Kapusta | K54: ITFO_GS_50 | L54: Kapusta.3ds | M54: 0.6 | N54: FALSE | O54: 3 | P54: 1 | Q54: 0 | R54: 0 | S54: =O54*P54 -> 3 | T54: =O54*Q54 -> 0 | U54: =O54*R54 -> 0 | V54: BRAK | W54: BRAK | X54: BRAK | Y54: BRAK | Z54: BRAK | AA54: BRAK | AB54: BRAK | AC54: BRAK | AD54: BRAK | AE54: 21600 | AF54: BRAK | AG54: BRAK | AH54: BRAK | AI54: BRAK | AJ54: BRAK | AK54: BRAK | AL54: BRAK | AM54: Rolnik
A55: Ziarno pszenicy | B55: Suchą rośline dalikatnie zmiel, a następnie odseperuj ziarenka | C55: ITEM_CAT_NONE | D55: - | E55: Common | F55: Common | G55: AdminCommon | H55: common | I55: TRUE | J55: itpl_SDRP_herb_37 | K55: ITMI_GS_COM_01 | L55: NASIONO18.3ds | M55: 0.05 | N55: FALSE | O55: BRAK | P55: BRAK | Q55: BRAK | R55: BRAK | S55: BRAK | T55: BRAK | U55: BRAK | V55: BRAK | W55: BRAK | X55: BRAK | Y55: BRAK | Z55: BRAK | AA55: BRAK | AB55: BRAK | AC55: BRAK | AD55: BRAK | AE55: BRAK | AF55: BRAK | AG55: BRAK | AH55: BRAK | AI55: BRAK | AJ55: BRAK | AK55: BRAK | AL55: T1 | AM55: Rolnik
A56: Nasiono marchwi | B56: Suchą rośline dalikatnie zmiel, a następnie odseperuj ziarenka | C56: ITEM_CAT_NONE | D56: - | E56: Common | F56: Common | G56: AdminCommon | H56: common | I56: TRUE | J56: itpl_SDRP_herb_48 | K56: ITMI_GS_COM_02 | L56: NASIONO29.3ds | M56: 0.05 | N56: FALSE | O56: BRAK | P56: BRAK | Q56: BRAK | R56: BRAK | S56: BRAK | T56: BRAK | U56: BRAK | V56: BRAK | W56: BRAK | X56: BRAK | Y56: BRAK | Z56: BRAK | AA56: BRAK | AB56: BRAK | AC56: BRAK | AD56: BRAK | AE56: BRAK | AF56: BRAK | AG56: BRAK | AH56: BRAK | AI56: BRAK | AJ56: BRAK | AK56: BRAK | AL56: T1 | AM56: Rolnik
A57: Wiązka słomy | B57: Wiązka słomy | C57: ITEM_CAT_ACSR2 | D57: - | E57: AccessorySlot2 | F57: Accessory | G57: AdminAccessory | H57: acsr2 | I57: TRUE | J57: LINK | K57: ITAC_GS_ACSR2_02 | L57: STATIC_KOZA_KLOSO_01.3ds | M57: 0.05 | N57: FALSE | O57: BRAK | P57: BRAK | Q57: BRAK | R57: BRAK | S57: BRAK | T57: BRAK | U57: BRAK | V57: BRAK | W57: BRAK | X57: BRAK | Y57: BRAK | Z57: BRAK | AA57: BRAK | AB57: BRAK | AC57: BRAK | AD57: BRAK | AE57: BRAK | AF57: BRAK | AG57: BRAK | AH57: BRAK | AI57: BRAK | AJ57: BRAK | AK57: BRAK | AL57: T1 | AM57: Rolnik
A58: Paczka lnu | B58: Ususzone włókna lnu zapakowane w małe paczki | C58: ITEM_CAT_NONE | D58: - | E58: Materials | F58: Materials | G58: AdminMaterials | H58: materials | I58: TRUE | J58: KM_ITMI_PACKET_03 | K58: ITMI_GS_MAT_05 | L58: KM_ITMI_PACKET_03.3ds | M58: 1 | N58: FALSE | O58: BRAK | P58: BRAK | Q58: BRAK | R58: BRAK | S58: BRAK | T58: BRAK | U58: BRAK | V58: BRAK | W58: BRAK | X58: BRAK | Y58: BRAK | Z58: BRAK | AA58: BRAK | AB58: BRAK | AC58: BRAK | AD58: BRAK | AE58: BRAK | AF58: BRAK | AG58: BRAK | AH58: BRAK | AI58: BRAK | AJ58: BRAK | AK58: BRAK | AL58: T1 | AM58: Rolnik
A59: Lina | B59: Wysuszone włókna poddaje się procesowi zaplatania | C59: ITEM_CAT_NONE | D59: - | E59: Materials | F59: Materials | G59: AdminMaterials | H59: materials | I59: TRUE | J59: ITMI_NACPANY | K59: ITMI_GS_MAT_06 | L59: IT_SlaveRope.3ds | M59: 1 | N59: FALSE | O59: BRAK | P59: BRAK | Q59: BRAK | R59: BRAK | S59: BRAK | T59: BRAK | U59: BRAK | V59: BRAK | W59: BRAK | X59: BRAK | Y59: BRAK | Z59: BRAK | AA59: BRAK | AB59: BRAK | AC59: BRAK | AD59: BRAK | AE59: BRAK | AF59: BRAK | AG59: BRAK | AH59: BRAK | AI59: BRAK | AJ59: BRAK | AK59: BRAK | AL59: T1 | AM59: Rolnik
A60: Ziarno lnu | B60: Suchą rośline dalikatnie zmiel, a następnie odseperuj ziarenka | C60: ITEM_CAT_NONE | D60: - | E60: Common | F60: Common | G60: AdminCommon | H60: common | I60: TRUE | J60: itpl_SDRP_herb_50 | K60: ITMI_GS_COM_03 | L60: NASIONO30.3ds | M60: 0.05 | N60: FALSE | O60: BRAK | P60: BRAK | Q60: BRAK | R60: BRAK | S60: BRAK | T60: BRAK | U60: BRAK | V60: BRAK | W60: BRAK | X60: BRAK | Y60: BRAK | Z60: BRAK | AA60: BRAK | AB60: BRAK | AC60: BRAK | AD60: BRAK | AE60: BRAK | AF60: BRAK | AG60: BRAK | AH60: BRAK | AI60: BRAK | AJ60: BRAK | AK60: BRAK | AL60: T1 | AM60: Rolnik
A61: Pasza | B61: Pasza stanowi jedzenie dla zwierząt hodowlanych | C61: ITEM_CAT_NONE | D61: - | E61: Common | F61: Common | G61: AdminCommon | H61: common | I61: TRUE | J61: PASZA | K61: ITMI_GS_COM_04 | L61: PASZA.3ds | M61: 1 | N61: FALSE | O61: BRAK | P61: BRAK | Q61: BRAK | R61: BRAK | S61: BRAK | T61: BRAK | U61: BRAK | V61: BRAK | W61: BRAK | X61: BRAK | Y61: BRAK | Z61: BRAK | AA61: BRAK | AB61: BRAK | AC61: BRAK | AD61: BRAK | AE61: BRAK | AF61: BRAK | AG61: BRAK | AH61: BRAK | AI61: BRAK | AJ61: BRAK | AK61: BRAK | AL61: T1 | AM61: Rolnik
A62: Nasiono rzepy | B62: Suchą rośline dalikatnie zmiel, a następnie odseperuj ziarenka | C62: ITEM_CAT_NONE | D62: - | E62: Common | F62: Common | G62: AdminCommon | H62: common | I62: TRUE | J62: itpl_SDRP_herb_31 | K62: ITMI_GS_COM_05 | L62: NASIONO12.3ds | M62: 0.05 | N62: FALSE | O62: BRAK | P62: BRAK | Q62: BRAK | R62: BRAK | S62: BRAK | T62: BRAK | U62: BRAK | V62: BRAK | W62: BRAK | X62: BRAK | Y62: BRAK | Z62: BRAK | AA62: BRAK | AB62: BRAK | AC62: BRAK | AD62: BRAK | AE62: BRAK | AF62: BRAK | AG62: BRAK | AH62: BRAK | AI62: BRAK | AJ62: BRAK | AK62: BRAK | AL62: T0 | AM62: Rolnik
A63: Pestka dyni | B63: Suchą rośline dalikatnie zmiel, a następnie odseperuj ziarenka | C63: ITEM_CAT_NONE | D63: - | E63: Common | F63: Common | G63: AdminCommon | H63: common | I63: TRUE | J63: itpl_SDRP_herb_69 | K63: ITMI_GS_COM_06 | L63: NASIONO28.3ds | M63: 0.05 | N63: FALSE | O63: BRAK | P63: BRAK | Q63: BRAK | R63: BRAK | S63: BRAK | T63: BRAK | U63: BRAK | V63: BRAK | W63: BRAK | X63: BRAK | Y63: BRAK | Z63: BRAK | AA63: BRAK | AB63: BRAK | AC63: BRAK | AD63: BRAK | AE63: BRAK | AF63: BRAK | AG63: BRAK | AH63: BRAK | AI63: BRAK | AJ63: BRAK | AK63: BRAK | AL63: T2 | AM63: Rolnik
A64: Paczka wełny | B64: Wełna zapakowane w małe paczuszki | C64: ITEM_CAT_NONE | D64: - | E64: Materials | F64: Materials | G64: AdminMaterials | H64: materials | I64: TRUE | J64: KM_ITMI_PACKET_07 | K64: ITMI_GS_MAT_07 | L64: KM_ITMI_PACKET_07.3ds | M64: 1.5 | N64: FALSE | O64: BRAK | P64: BRAK | Q64: BRAK | R64: BRAK | S64: BRAK | T64: BRAK | U64: BRAK | V64: BRAK | W64: BRAK | X64: BRAK | Y64: BRAK | Z64: BRAK | AA64: BRAK | AB64: BRAK | AC64: BRAK | AD64: BRAK | AE64: BRAK | AF64: BRAK | AG64: BRAK | AH64: BRAK | AI64: BRAK | AJ64: BRAK | AK64: BRAK | AL64: T2 | AM64: Rolnik
A65: Nasiono kapusty | B65: Suchą rośline dalikatnie zmiel, a następnie odseperuj ziarenka | C65: ITEM_CAT_NONE | D65: - | E65: Common | F65: Common | G65: AdminCommon | H65: common | I65: TRUE | J65: itpl_SDRP_herb_21 | K65: ITMI_GS_COM_07 | L65: NASIONO2.3ds | M65: 0.05 | N65: FALSE | O65: BRAK | P65: BRAK | Q65: BRAK | R65: BRAK | S65: BRAK | T65: BRAK | U65: BRAK | V65: BRAK | W65: BRAK | X65: BRAK | Y65: BRAK | Z65: BRAK | AA65: BRAK | AB65: BRAK | AC65: BRAK | AD65: BRAK | AE65: BRAK | AF65: BRAK | AG65: BRAK | AH65: BRAK | AI65: BRAK | AJ65: BRAK | AK65: BRAK | AL65: T3 | AM65: Rolnik
A66: =HYPERLINK("https://imgur.com/fMgtFfX","Mączka kostna") -> Mączka kostna | B66: Przemielone kości idealnie nadające się do użyźnienia gleby | C66: ITEM_CAT_NONE | D66: - | E66: Common | F66: Common | G66: AdminCommon | H66: common | I66: TRUE | J66: ITCR_SDRP_INGR_21 | K66: ITMI_GS_COM_08 | L66: ItMi_Pocket.3ds | M66: 0.5 | N66: FALSE | O66: BRAK | P66: BRAK | Q66: BRAK | R66: BRAK | S66: BRAK | T66: BRAK | U66: BRAK | V66: BRAK | W66: BRAK | X66: BRAK | Y66: BRAK | Z66: BRAK | AA66: BRAK | AB66: BRAK | AC66: BRAK | AD66: BRAK | AE66: BRAK | AF66: BRAK | AG66: BRAK | AH66: BRAK | AI66: BRAK | AJ66: BRAK | AK66: BRAK | AL66: T1 | AM66: Rolnik
...

Sheet All instancje z modelami saga 3
A1: Instancja | B1: Model (visual) | C1: Visual Change | D1: Nazwa (name)
A2: itam_addon_franco | B2: ItAm_Hp_01.3ds
A3: itam_addon_health | B3: ItAm_Hp_01.3ds
A4: itri_addon_health_01 | B4: ItRi_Prot_Total_01.3ds
A5: itri_addon_health_02 | B5: ItRi_Prot_Total_01.3ds
A6: itam_addon_mana | B6: ItAm_Hp_01.3ds
A7: itri_addon_mana_01 | B7: ItRi_Prot_Total_01.3ds
A8: itri_addon_mana_02 | B8: ItRi_Prot_Total_01.3ds
A9: itam_addon_str | B9: ItAm_Hp_01.3ds
A10: itri_addon_str_01 | B10: ItRi_Prot_Total_02.3ds
A11: itri_addon_str_02 | B11: ItRi_Prot_Total_02.3ds
A12: itar_pir_l_addon | B12: ItAr_PIR_L_ADDON.3ds | C12: Armor_Pir_L_Addon.ASC | D12: Piratenkleidung
A13: itar_pir_m_addon | B13: ItAr_PIR_M_ADDON.3ds | C13: Armor_PIR_M_ADDON.asc | D13: Piratenrüstung
A14: itar_pir_h_addon | B14: ItAr_PIR_H_ADDON.3ds | C14: Armor_PIR_H_ADDON.asc | D14: Kapitäns Kleidung
A15: itar_thorus_addon | B15: ItAr_Thorus_ADDON.3ds | C15: Armor_Thorus_ADDON.asc | D15: Schwere Gardistenrüstung
A16: itar_raven_addon | B16: ItAr_Raven_ADDON.3ds | C16: Armor_Raven_ADDON.asc | D16: Ravens Rüstung
A17: itar_orebaron_addon | B17: ItAr_CHAOS_ADDON.3ds | C17: Armor_CHAOS_ADDON.asc | D17: Erzbaronrüstung
A18: itar_ranger_addon | B18: ItAr_Ranger_ADDON.3ds | C18: Armor_Ranger_ADDON.asc | D18: Rüstung des 'Rings des Wassers'
A19: itar_fake_ranger | B19: ItAr_Ranger_ADDON.3ds | C19: Armor_Ranger_ADDON.asc | D19: zerissene Rüstung
A20: itar_kdw_l_addon | B20: ItAr_KDW_L_ADDON.3ds | C20: Armor_KDW_L_ADDON.asc | D20: Leichte KDW
A21: itar_bloodwyn_addon | B21: ItAr_Bloodwyn_ADDON.3ds | C21: Armor_Bloodwyn_ADDON.asc | D21: Bloodwyn Rüstung
A22: itar_mayazombie_addon | B22: ItAr_Raven_ADDON.3ds | C22: Armor_MayaZombie_Addon.asc | D22: alte Rüstung
A23: itar_firearmor_addon | B23: ItAr_Xardas.3ds | C23: Armor_Xardas.asc | D23: Magische Rüstung
A24: itbe_addon_leather_01 | B24: ItMI_Belt_06.3ds
A25: itbe_addon_sld_01 | B25: ItMi_Belt_05.3ds
A26: itbe_addon_nov_01 | B26: ItMi_Belt_02.3ds
A27: itbe_addon_mil_01 | B27: ItMi_Belt_03.3ds
A28: itbe_addon_kdf_01 | B28: ItMi_Belt_02.3ds
A29: itbe_addon_mc | B29: ItMi_Belt_08.3ds
A30: itbe_addon_str_5 | B30: ItMi_Belt_08.3ds
A31: itbe_addon_str_10 | B31: ItMi_Belt_05.3ds
A32: itbe_addon_dex_5 | B32: ItMi_Belt_08.3ds
A33: itbe_addon_dex_10 | B33: ItMi_Belt_05.3ds
A34: itbe_addon_prot_edge | B34: ItMi_Belt_02.3ds
A35: itbe_addon_prot_point | B35: ItMi_Belt_02.3ds
... A39: itbe_addon_prot_total | B39: ItMi_Belt_02.3ds
A40: itfo_addon_shellflesh | B40: ItAt_Meatbugflesh.3DS | D40: Muschelfleisch
A41: itfo_addon_rum | B41: ItMi_Rum_02.3ds | D41: Rum
A42: itfo_addon_grog | B42: ItMi_Rum_02.3ds | D42: Grog
A43: itfo_addon_loushammer | B43: ItMi_Rum_01.3ds | D43: Lou's Hammer
...

Sheet Lista mebli
A1: Nazwa | B1: Tier | C1: Opis | D1: Instancja | E1: Instancja [Saga3] | F1: Składnik 1 | H1: Składnik 2 | J1: Składnik 3 | L1: Składnik 4 | N1: Składnik 5 | P1: Składnik 6 | R1: Składnik 7 | T1: Składnik 8 | V1: Składnik 9 | X1: Składnik 10 | Z1: Składnik 11 | AB1: Składnik 12 | AD1: Waga | AE1: VobType | AF1: category | AG1: Do mieszkania? | AH1: Dla graczy | AI1: Cena
F3: Nazwa | G3: Ilość | H3: Nazwa | I3: Ilość | J3: Nazwa | K3: Ilość | L3: Nazwa | M3: Ilość | N3: Nazwa | O3: Ilość | P3: Nazwa | Q3: Ilość | R3: Nazwa | S3: Ilość | T3: Nazwa | U3: Ilość | V3: Nazwa | W3: Ilość | X3: Nazwa | Y3: Ilość | Z3: Nazwa | AA3: Ilość | AB3: Nazwa | AC3: Ilość
A4: Drewniana skrzynia | B4: 1 | C4: Drewniana skrzynia. | D4: CHESTSMALL_OCCHESTSMALLLOCKED.ASC | E4: CHESTSMALL_OCCHESTSMALLLOCKED.ASC | F4: Deska z miękiego drewna | G4: 13 | H4: Gwoździe | I4: 1 | J4: Smoła | K4: 1 | L4: Żelazne elementy | M4: 1 | N4: - | P4: - | R4: - | T4: - | V4: - | X4: - | Z4: - | AB4: - | AD4: 20 | AE4: MobInter | AF4: chest | AG4: TRUE | AH4: TRUE | AI4: =IFERROR(VLOOKUP(F4,Cennik!$A$4:$B892, 2, FALSE()) * G4 + VLOOKUP(H4,Cennik!$A$4:$B892, 2, FALSE()) * I4 + VLOOKUP(J4,Cennik!$A$4:$B892, 2, FALSE()) * K4 + VLOOKUP(L4,Cennik!$A$4:$B892, 2, FALSE()) * M4 + VLOOKUP(N4,Cennik!$A$4:$B892, 2, FALSE()) * O4 + VLOOKUP(P4,Cennik!$A$4:$B892, 2, FALSE()) * Q4 + VLOOKUP(R4,Cennik!$A$4:$B892, 2, FALSE()) * S4 + VLOOKUP(T4,Cennik!$A$4:$B892, 2, FALSE()) * U4 + VLOOKUP(V4,Cennik!$A$4:$B892, 2, FALSE()) * W4 + VLOOKUP(X4,Cennik!$A$4:$B892, 2, FALSE()) * Y4 + VLOOKUP(Z4,Cennik!$A$4:$B892, 2, FALSE()) * AA4 + VLOOKUP(AB4,Cennik!$A$4:$B892, 2, FALSE() * AC4),"Brak wartości") -> Brak wartości
A5: Mała prowizoryczna skrzynia | B5: 1 | C5: Mala prowizoryczna skrzynia | D5: CHESTSMALL_OCCRATESMALLLOCKED.ASC | E5: CHESTSMALL_OCCRATESMALLLOCKED.ASC | F5: Deska z miękiego drewna | G5: 10 | H5: Smoła | I5: 1 | J5: Gwoździe | K5: 2 | L5: Żelazne elementy | M5: 1 | N5: - | P5: - | R5: - | T5: - | V5: - | X5: - | Z5: - | AB5: - | AD5: 10 | AE5: MobInter | AF5: chest | AG5: TRUE | AH5: TRUE | AI5: =IFERROR(VLOOKUP(F5,Cennik!$A$4:$B892, 2, FALSE()) * G5 + VLOOKUP(H5,Cennik!$A$4:$B892, 2, FALSE()) * I5 + VLOOKUP(J5,Cennik!$A$4:$B892, 2, FALSE()) * K5 + VLOOKUP(L5,Cennik!$A$4:$B892, 2, FALSE()) * M5 + VLOOKUP(N5,Cennik!$A$4:$B892, 2, FALSE()) * O5 + VLOOKUP(P5,Cennik!$A$4:$B892, 2, FALSE()) * Q5 + VLOOKUP(R5,Cennik!$A$4:$B892, 2, FALSE()) * S5 + VLOOKUP(T5,Cennik!$A$4:$B892, 2, FALSE()) * U5 + VLOOKUP(V5,Cennik!$A$4:$B892, 2, FALSE()) * W5 + VLOOKUP(X5,Cennik!$A$4:$B892, 2, FALSE()) * Y5 + VLOOKUP(Z5,Cennik!$A$4:$B892, 2, FALSE()) * AA5 + VLOOKUP(AB5,Cennik!$A$4:$B892, 2, FALSE() * AC5),"Brak wartości") -> Brak wartości
A6: Duża prowizoryczna skrzynia | B6: 1 | C6: Duża prowizoryczna skrzynia | D6: CHESTBIG_OCCRATELARGELOCKED.ASC | E6: CHESTBIG_OCCRATELARGELOCKED.ASC | F6: Deska z miękiego drewna | G6: 20 | H6: Smoła | I6: 1 | J6: Gwoździe | K6: 2 | L6: Żelazne elementy | M6: 1 | N6: - | P6: - | R6: - | T6: - | V6: - | X6: - | Z6: - | AB6: - | AD6: 30 | AE6: MobInter | AF6: chest | AG6: TRUE | AH6: TRUE | AI6: =IFERROR(VLOOKUP(F6,Cennik!$A$4:$B892, 2, FALSE()) * G6 + VLOOKUP(H6,Cennik!$A$4:$B892, 2, FALSE()) * I6 + VLOOKUP(J6,Cennik!$A$4:$B892, 2, FALSE()) * K6 + VLOOKUP(L6,Cennik!$A$4:$B892, 2, FALSE()) * M6 + VLOOKUP(N6,Cennik!$A$4:$B892, 2, FALSE()) * O6 + VLOOKUP(P6,Cennik!$A$4:$B892, 2, FALSE()) * Q6 + VLOOKUP(R6,Cennik!$A$4:$B892, 2, FALSE()) * S6 + VLOOKUP(T6,Cennik!$A$4:$B892, 2, FALSE()) * U6 + VLOOKUP(V6,Cennik!$A$4:$B892, 2, FALSE()) * W6 + VLOOKUP(X6,Cennik!$A$4:$B892, 2, FALSE()) * Y6 + VLOOKUP(Z6,Cennik!$A$4:$B892, 2, FALSE()) * AA6 + VLOOKUP(AB6,Cennik!$A$4:$B892, 2, FALSE() * AC6),"Brak wartości") -> Brak wartości
A7: Beczka | B7: 1 | C7: Nie dajmy się zwieść wyglądowi, beczka może mieć w sobie więcej, niż się spodziewamy. | D7: KM_VOB_BARRELTABLE_02.3DS | E7: KM_VOB_BARRELTABLE_02.3DS | F7: Deska z miękiego drewna | G7: 10 | H7: Gwoździe | I7: 2 | J7: Żelazny pręt | K7: 1 | L7: Smoła | M7: 1 | N7: - | P7: - | R7: - | T7: - | V7: - | X7: - | Z7: - | AB7: - | AD7: 15 | AE7: MobInter | AF7: chest | AG7: TRUE | AH7: TRUE | AI7: =IFERROR(VLOOKUP(F7,Cennik!$A$4:$B892, 2, FALSE()) * G7 + VLOOKUP(H7,Cennik!$A$4:$B892, 2, FALSE()) * I7 + VLOOKUP(J7,Cennik!$A$4:$B892, 2, FALSE()) * K7 + VLOOKUP(L7,Cennik!$A$4:$B892, 2, FALSE()) * M7 + VLOOKUP(N7,Cennik!$A$4:$B892, 2, FALSE()) * O7 + VLOOKUP(P7,Cennik!$A$4:$B892, 2, FALSE()) * Q7 + VLOOKUP(R7,Cennik!$A$4:$B892, 2, FALSE()) * S7 + VLOOKUP(T7,Cennik!$A$4:$B892, 2, FALSE()) * U7 + VLOOKUP(V7,Cennik!$A$4:$B892, 2, FALSE()) * W7 + VLOOKUP(X7,Cennik!$A$4:$B892, 2, FALSE()) * Y7 + VLOOKUP(Z7,Cennik!$A$4:$B892, 2, FALSE()) * AA7 + VLOOKUP(AB7,Cennik!$A$4:$B892, 2, FALSE() * AC7),"Brak wartości") -> Brak wartości
A8: Skrzynia na drewno | B8: 1 | C8: Skrzynia na drewno | D8: OC_FIREWOOD_V2.ASC | E8: OC_FIREWOOD_V2.3ds | F8: Deska z miękiego drewna | G8: 5 | H8: Smoła | I8: 1 | J8: - | L8: - | N8: - | P8: - | R8: - | T8: - | V8: - | X8: - | Z8: - | AB8: - | AD8: 10 | AE8: MobInter | AF8: chest | AG8: TRUE | AH8: TRUE | AI8: =IFERROR(VLOOKUP(F8,Cennik!$A$4:$B892, 2, FALSE()) * G8 + VLOOKUP(H8,Cennik!$A$4:$B892, 2, FALSE()) * I8 + VLOOKUP(J8,Cennik!$A$4:$B892, 2, FALSE()) * K8 + VLOOKUP(L8,Cennik!$A$4:$B892, 2, FALSE()) * M8 + VLOOKUP(N8,Cennik!$A$4:$B892, 2, FALSE()) * O8 + VLOOKUP(P8,Cennik!$A$4:$B892, 2, FALSE()) * Q8 + VLOOKUP(R8,Cennik!$A$4:$B892, 2, FALSE()) * S8 + VLOOKUP(T8,Cennik!$A$4:$B892, 2, FALSE()) * U8 + VLOOKUP(V8,Cennik!$A$4:$B892, 2, FALSE()) * W8 + VLOOKUP(X8,Cennik!$A$4:$B892, 2, FALSE()) * Y8 + VLOOKUP(Z8,Cennik!$A$4:$B892, 2, FALSE()) * AA8 + VLOOKUP(AB8,Cennik!$A$4:$B892, 2, FALSE() * AC8),"Brak wartości") -> Brak wartości
A9: Biedna skrzynia | B9: 2 | C9: Niby biedna a jednak lepsza niż prowizoryczne. | D9: CHESTSMALL_NW_POOR_LOCKED.ASC | E9: CHESTSMALL_NW_POOR_LOCKED.ASC | F9: Twarde drewno | G9: 1 | H9: Deska z twardego drewna | I9: 4 | J9: Gwoździe | K9: 2 | L9: Smoła | M9: 1 | N9: Sztaba żelaza | O9: 1 | P9: Żelazne elementy | Q9: 1 | R9: - | T9: - | V9: - | X9: - | Z9: - | AB9: - | AD9: 25 | AE9: MobInter | AF9: chest | AG9: TRUE | AH9: TRUE | AI9: =IFERROR(VLOOKUP(F9,Cennik!$A$4:$B892, 2, FALSE()) * G9 + VLOOKUP(H9,Cennik!$A$4:$B892, 2, FALSE()) * I9 + VLOOKUP(J9,Cennik!$A$4:$B892, 2, FALSE()) * K9 + VLOOKUP(L9,Cennik!$A$4:$B892, 2, FALSE()) * M9 + VLOOKUP(N9,Cennik!$A$4:$B892, 2, FALSE()) * O9 + VLOOKUP(P9,Cennik!$A$4:$B892, 2, FALSE()) * Q9 + VLOOKUP(R9,Cennik!$A$4:$B892, 2, FALSE()) * S9 + VLOOKUP(T9,Cennik!$A$4:$B892, 2, FALSE()) * U9 + VLOOKUP(V9,Cennik!$A$4:$B892, 2, FALSE()) * W9 + VLOOKUP(X9,Cennik!$A$4:$B892, 2, FALSE()) * Y9 + VLOOKUP(Z9,Cennik!$A$4:$B892, 2, FALSE()) * AA9 + VLOOKUP(AB9,Cennik!$A$4:$B892, 2, FALSE() * AC9),"Brak wartości") -> Brak wartości
A10: Duży drewniany kufer | B10: 2 | C10: Skrzynia będzie posiadała liczne okucia z pretów oraz blach. | D10: CHESTBIG_OCCHESTMEDIUMLOCKED.ASC | E10: CHESTBIG_OCCHESTMEDIUMLOCKED.ASC | F10: Twarde drewno | G10: 2 | H10: Deska z twardego drewna | I10: 6 | J10: Gwoździe | K10: 3 | L10: Smoła | M10: 2 | N10: Sztaba żelaza | O10: 2 | P10: Żelazne elementy | Q10: 1 | R10: - | T10: - | V10: - | X10: - | Z10: - | AB10: - | AD10: 40 | AE10: MobInter | AF10: chest | AG10: TRUE | AH10: TRUE | AI10: =IFERROR(VLOOKUP(F10,Cennik!$A$4:$B892, 2, FALSE()) * G10 + VLOOKUP(H10,Cennik!$A$4:$B892, 2, FALSE()) * I10 + VLOOKUP(J10,Cennik!$A$4:$B892, 2, FALSE()) * K10 + VLOOKUP(L10,Cennik!$A$4:$B892, 2, FALSE()) * M10 + VLOOKUP(N10,Cennik!$A$4:$B892, 2, FALSE()) * O10 + VLOOKUP(P10,Cennik!$A$4:$B892, 2, FALSE()) * Q10 + VLOOKUP(R10,Cennik!$A$4:$B892, 2, FALSE()) * S10 + VLOOKUP(T10,Cennik!$A$4:$B892, 2, FALSE()) * U10 + VLOOKUP(V10,Cennik!$A$4:$B892, 2, FALSE()) * W10 + VLOOKUP(X10,Cennik!$A$4:$B892, 2, FALSE()) * Y10 + VLOOKUP(Z10,Cennik!$A$4:$B892, 2, FALSE()) * AA10 + VLOOKUP(AB10,Cennik!$A$4:$B892, 2, FALSE() * AC10),"Brak wartości") -> Brak wartości
A11: Mała wzmacniana skrzynia | B11: 3 | C11: Skrzynia będzie posiadała liczne okucia z pretów oraz blach. | D11: CHESTSMALL_NW_NORMAL_LOCKED.ASC | E11: CHESTBIG_NW_NORMAL_LOCKED.mds | F11: Szlachetne drewno | G11: 2 | H11: Deska z miękiego drewna | I11: 8 | J11: Deska z szlachetnego drewna | K11: 4 | L11: Gwoździe | M11: 3 | N11: Smoła | O11: 2 | P11: Sztabka stali | Q11: 1 | R11: Żelazne elementy | S11: 2 | T11: - | V11: - | X11: - | Z11: - | AB11: - | AD11: 35 | AE11: MobInter | AF11: chest | AG11: TRUE | AH11: TRUE | AI11: =IFERROR(VLOOKUP(F11,Cennik!$A$4:$B892, 2, FALSE()) * G11 + VLOOKUP(H11,Cennik!$A$4:$B892, 2, FALSE()) * I11 + VLOOKUP(J11,Cennik!$A$4:$B892, 2, FALSE()) * K11 + VLOOKUP(L11,Cennik!$A$4:$B892, 2, FALSE()) * M11 + VLOOKUP(N11,Cennik!$A$4:$B892, 2, FALSE()) * O11 + VLOOKUP(P11,Cennik!$A$4:$B892, 2, FALSE()) * Q11 + VLOOKUP(R11,Cennik!$A$4:$B892, 2, FALSE()) * S11 + VLOOKUP(T11,Cennik!$A$4:$B892, 2, FALSE()) * U11 + VLOOKUP(V11,Cennik!$A$4:$B892, 2, FALSE()) * W11 + VLOOKUP(X11,Cennik!$A$4:$B892, 2, FALSE()) * Y11 + VLOOKUP(Z11,Cennik!$A$4:$B892, 2, FALSE()) * AA11 + VLOOKUP(AB11,Cennik!$A$4:$B892, 2, FALSE() * AC11),"Brak wartości") -> Brak wartości
A12: Duża wzmacniana skrzynia | B12: 3 | C12: Skrzynia będzie posiadała jeszcze więcej okuć niż wersja mniejsza. | D12: CHESTBIG_NW_NORMAL_LOCKED.ASC | E12: CHESTBIG_NW_NORMAL_LOCKED.ASC | F12: Szlachetne drewno | G12: 4 | H12: Deska z miękiego drewna | I12: 12 | J12: Deska z szlachetnego drewna | K12: 6 | L12: Gwoździe | M12: 4 | N12: Smoła | O12: 2 | P12: Sztabka stali | Q12: 1 | R12: Żelazne elementy | S12: 2 | T12: - | V12: - | X12: - | Z12: - | AB12: - | AD12: 50 | AE12: MobInter | AF12: chest | AG12: TRUE | AH12: TRUE | AI12: =IFERROR(VLOOKUP(F12,Cennik!$A$4:$B892, 2, FALSE()) * G12 + VLOOKUP(H12,Cennik!$A$4:$B892, 2, FALSE()) * I12 + VLOOKUP(J12,Cennik!$A$4:$B892, 2, FALSE()) * K12 + VLOOKUP(L12,Cennik!$A$4:$B892, 2, FALSE()) * M12 + VLOOKUP(N12,Cennik!$A$4:$B892, 2, FALSE()) * O12 + VLOOKUP(P12,Cennik!$A$4:$B892, 2, FALSE()) * Q12 + VLOOKUP(R12,Cennik!$A$4:$B892, 2, FALSE()) * S12 + VLOOKUP(T12,Cennik!$A$4:$B892, 2, FALSE()) * U12 + VLOOKUP(V12,Cennik!$A$4:$B892, 2, FALSE()) * W12 + VLOOKUP(X12,Cennik!$A$4:$B892, 2, FALSE()) * Y12 + VLOOKUP(Z12,Cennik!$A$4:$B892, 2, FALSE()) * AA12 + VLOOKUP(AB12,Cennik!$A$4:$B892, 2, FALSE() * AC12),"Brak wartości") -> Brak wartości
A13: Solidna skrzynia | B13: 4 | C13: Solidna skrzynia | D13: CHESTBIG_NW_RICH_LOCKED.ASC | E13: CHESTBIG_NW_RICH_LOCKED.ASC | F13: Szlachetne drewno | G13: 5 | H13: Deska z szlachetnego drewna | I13: 8 | J13: Gwoździe | K13: 8 | L13: Smoła | M13: 3 | N13: Sztabka stali | O13: 1 | P13: Żelazny pręt | Q13: 5 | R13: Żelazne elementy | S13: 3 | T13: - | V13: - | X13: - | Z13: - | AB13: - | AD13: 60 | AE13: MobInter | AF13: chest | AG13: TRUE | AH13: TRUE | AI13: =IFERROR(VLOOKUP(F13,Cennik!$A$4:$B892, 2, FALSE()) * G13 + VLOOKUP(H13,Cennik!$A$4:$B892, 2, FALSE()) * I13 + VLOOKUP(J13,Cennik!$A$4:$B892, 2, FALSE()) * K13 + VLOOKUP(L13,Cennik!$A$4:$B892, 2, FALSE()) * M13 + VLOOKUP(N13,Cennik!$A$4:$B892, 2, FALSE()) * O13 + VLOOKUP(P13,Cennik!$A$4:$B892, 2, FALSE()) * Q13 + VLOOKUP(R13,Cennik!$A$4:$B892, 2, FALSE()) * S13 + VLOOKUP(T13,Cennik!$A$4:$B892, 2, FALSE()) * U13 + VLOOKUP(V13,Cennik!$A$4:$B892, 2, FALSE()) * W13 + VLOOKUP(X13,Cennik!$A$4:$B892, 2, FALSE()) * Y13 + VLOOKUP(Z13,Cennik!$A$4:$B892, 2, FALSE()) * AA13 + VLOOKUP(AB13,Cennik!$A$4:$B892, 2, FALSE() * AC13),"Brak wartości") -> Brak wartości
A14: Stalowy kufer | B14: 4 | C14: Solidna skrzynia | D14: ItHc_Chest_Silver.3DS | E14: CHESTBIG_SILVEROPEN_LOCKED.MDS | F14: Szlachetne drewno | G14: 6 | H14: Deska z szlachetnego drewna | I14: 12 | J14: Gwoździe | K14: 8 | L14: Smoła | M14: 4 | N14: Sztabka stali | O14: 1 | P14: Żelazna blacha | Q14: 10 | R14: Żelazny pręt | S14: 5 | T14: Żelazne elementy | U14: 3 | V14: - | X14: - | Z14: - | AB14: - | AD14: 60 | AE14: MobInter | AF14: chest | AG14: TRUE | AH14: TRUE | AI14: =IFERROR(VLOOKUP(F14,Cennik!$A$4:$B892, 2, FALSE()) * G14 + VLOOKUP(H14,Cennik!$A$4:$B892, 2, FALSE()) * I14 + VLOOKUP(J14,Cennik!$A$4:$B892, 2, FALSE()) * K14 + VLOOKUP(L14,Cennik!$A$4:$B892, 2, FALSE()) * M14 + VLOOKUP(N14,Cennik!$A$4:$B892, 2, FALSE()) * O14 + VLOOKUP(P14,Cennik!$A$4:$B892, 2, FALSE()) * Q14 + VLOOKUP(R14,Cennik!$A$4:$B892, 2, FALSE()) * S14 + VLOOKUP(T14,Cennik!$A$4:$B892, 2, FALSE()) * U14 + VLOOKUP(V14,Cennik!$A$4:$B892, 2, FALSE()) * W14 + VLOOKUP(X14,Cennik!$A$4:$B892, 2, FALSE()) * Y14 + VLOOKUP(Z14,Cennik!$A$4:$B892, 2, FALSE()) * AA14 + VLOOKUP(AB14,Cennik!$A$4:$B892, 2, FALSE() * AC14),"Brak wartości") -> Brak wartości
A15: Varancki skarbiec | B15: 5 | C15: Majestatyczny kufer zdobiony misternymi drzeworytami i ornamentami, który przechowuje skarby godne samego króla Rhobara. | D15: KM_VOB_GOLD_HEAP_01.ASC | E15: KM_VOB_GOLD_HEAP_01.3ds | F15: - | H15: - | J15: - | L15: - | N15: - | P15: - | R15: - | T15: - | V15: - | X15: - | Z15: - | AB15: - | AD15: 80 | AE15: MobInter | AF15: chest | AG15: FALSE | AH15: FALSE | AI15: 2000
A16: Królewska skrzynia | B16: 5 | C16: Majestatyczny kufer zdobiony misternymi drzeworytami i ornamentami, który przechowuje skarby godne samego króla Rhobara. | D16: ItHc_Chest_Gold.3DS | E16: CHESTBIG_GOLDOPEN_LOCKED.MDS | F16: Szlachetne drewno | G16: 8 | H16: Gwoździe | I16: 5 | J16: Smoła | K16: 5 | L16: Stalowy pręt | M16: 4 | N16: Moneta | O16: 1000 | P16: Żelazne elementy | Q16: 4 | R16: - | T16: - | V16: - | X16: - | Z16: - | AB16: - | AD16: 80 | AE16: MobInter | AF16: chest | AG16: TRUE | AH16: TRUE | AI16: =IFERROR(VLOOKUP(F16,Cennik!$A$4:$B892, 2, FALSE()) * G16 + VLOOKUP(H16,Cennik!$A$4:$B892, 2, FALSE()) * I16 + VLOOKUP(J16,Cennik!$A$4:$B892, 2, FALSE()) * K16 + VLOOKUP(L16,Cennik!$A$4:$B892, 2, FALSE()) * M16 + VLOOKUP(N16,Cennik!$A$4:$B892, 2, FALSE()) * O16 + VLOOKUP(P16,Cennik!$A$4:$B892, 2, FALSE()) * Q16 + VLOOKUP(R16,Cennik!$A$4:$B892, 2, FALSE()) * S16 + VLOOKUP(T16,Cennik!$A$4:$B892, 2, FALSE()) * U16 + VLOOKUP(V16,Cennik!$A$4:$B892, 2, FALSE()) * W16 + VLOOKUP(X16,Cennik!$A$4:$B892, 2, FALSE()) * Y16 + VLOOKUP(Z16,Cennik!$A$4:$B892, 2, FALSE()) * AA16 + VLOOKUP(AB16,Cennik!$A$4:$B892, 2, FALSE() * AC16),"Brak wartości") -> Brak wartości
F17: - | H17: - | J17: - | L17: - | N17: - | P17: - | R17: - | T17: - | V17: - | X17: - | Z17: - | AB17: -
F18: - | H18: - | J18: - | L18: - | N18: - | P18: - | R18: - | T18: - | V18: - | X18: - | Z18: - | AB18: -
F19: - | H19: - | J19: - | L19: - | N19: - | P19: - | R19: - | T19: - | V19: - | X19: - | Z19: - | AB19: -
A20: Zbity drewniany stolik | B20: 1 | C20: Stół zrobiony z resztek, ale i tak wydaje się dość solidny. Może służyć do różnych celów. | D20: PC_LOB_TABLE2.3ds | E20: PC_LOB_TABLE2.3ds | F20: Deska z miękiego drewna | G20: 5 | H20: Gwoździe | I20: 1 | J20: Smoła | K20: 1 | L20: - | N20: - | P20: - | R20: - | T20: - | V20: - | X20: - | Z20: - | AB20: - | AD20: 5 | AE20: Vob | AF20: table | AG20: TRUE | AH20: TRUE | AI20: =IFERROR(VLOOKUP(F20,Cennik!$A$4:$B892, 2, FALSE()) * G20 + VLOOKUP(H20,Cennik!$A$4:$B892, 2, FALSE()) * I20 + VLOOKUP(J20,Cennik!$A$4:$B892, 2, FALSE()) * K20 + VLOOKUP(L20,Cennik!$A$4:$B892, 2, FALSE()) * M20 + VLOOKUP(N20,Cennik!$A$4:$B892, 2, FALSE()) * O20 + VLOOKUP(P20,Cennik!$A$4:$B892, 2, FALSE()) * Q20 + VLOOKUP(R20,Cennik!$A$4:$B892, 2, FALSE()) * S20 + VLOOKUP(T20,Cennik!$A$4:$B892, 2, FALSE()) * U20 + VLOOKUP(V20,Cennik!$A$4:$B892, 2, FALSE()) * W20 + VLOOKUP(X20,Cennik!$A$4:$B892, 2, FALSE()) * Y20 + VLOOKUP(Z20,Cennik!$A$4:$B892, 2, FALSE()) * AA20 + VLOOKUP(AB20,Cennik!$A$4:$B892, 2, FALSE() * AC20),"Brak wartości") -> Brak wartości
A21: Stół z pniaka | B21: 1 | C21: Stół zrobiony z resztek, ale i tak wydaje się dość solidny. Może służyć do różnych celów. | D21: NC_LOB_TABLE2.3ds | E21: NC_LOB_TABLE2.3ds | F21: Deska z miękiego drewna | G21: 5 | H21: Gwoździe | I21: 1 | J21: Smoła | K21: 1 | L21: - | N21: - | P21: - | R21: - | T21: - | V21: - | X21: - | Z21: - | AB21: - | AD21: 5 | AE21: Vob | AF21: table | AG21: TRUE | AH21: TRUE | AI21: =IFERROR(VLOOKUP(F21,Cennik!$A$4:$B892, 2, FALSE()) * G21 + VLOOKUP(H21,Cennik!$A$4:$B892, 2, FALSE()) * I21 + VLOOKUP(J21,Cennik!$A$4:$B892, 2, FALSE()) * K21 + VLOOKUP(L21,Cennik!$A$4:$B892, 2, FALSE()) * M21 + VLOOKUP(N21,Cennik!$A$4:$B892, 2, FALSE()) * O21 + VLOOKUP(P21,Cennik!$A$4:$B892, 2, FALSE()) * Q21 + VLOOKUP(R21,Cennik!$A$4:$B892, 2, FALSE()) * S21 + VLOOKUP(T21,Cennik!$A$4:$B892, 2, FALSE()) * U21 + VLOOKUP(V21,Cennik!$A$4:$B892, 2, FALSE()) * W21 + VLOOKUP(X21,Cennik!$A$4:$B892, 2, FALSE()) * Y21 + VLOOKUP(Z21,Cennik!$A$4:$B892, 2, FALSE()) * AA21 + VLOOKUP(AB21,Cennik!$A$4:$B892, 2, FALSE() * AC21),"Brak wartości") -> Brak wartości
A22: Prowizoryczny stół | B22: 1 | C22: Stół zrobiony z resztek, ale i tak wydaje się dość solidny. Może służyć do różnych celów. | D22: OC_TABLE_V3.3ds | E22: OC_TABLE_V3.3ds | F22: Deska z miękiego drewna | G22: 10 | H22: Gwoździe | I22: 1 | J22: Smoła | K22: 1 | L22: - | N22: - | P22: - | R22: - | T22: - | V22: - | X22: - | Z22: - | AB22: - | AD22: 5 | AE22: Vob | AF22: table | AG22: TRUE | AH22: TRUE | AI22: =IFERROR(VLOOKUP(F22,Cennik!$A$4:$B892, 2, FALSE()) * G22 + VLOOKUP(H22,Cennik!$A$4:$B892, 2, FALSE()) * I22 + VLOOKUP(J22,Cennik!$A$4:$B892, 2, FALSE()) * K22 + VLOOKUP(L22,Cennik!$A$4:$B892, 2, FALSE()) * M22 + VLOOKUP(N22,Cennik!$A$4:$B892, 2, FALSE()) * O22 + VLOOKUP(P22,Cennik!$A$4:$B892, 2, FALSE()) * Q22 + VLOOKUP(R22,Cennik!$A$4:$B892, 2, FALSE()) * S22 + VLOOKUP(T22,Cennik!$A$4:$B892, 2, FALSE()) * U22 + VLOOKUP(V22,Cennik!$A$4:$B892, 2, FALSE()) * W22 + VLOOKUP(X22,Cennik!$A$4:$B892, 2, FALSE()) * Y22 + VLOOKUP(Z22,Cennik!$A$4:$B892, 2, FALSE()) * AA22 + VLOOKUP(AB22,Cennik!$A$4:$B892, 2, FALSE() * AC22),"Brak wartości") -> Brak wartości
A23: Okrągły prowizoryczny stół | B23: 1 | C23: Stół zrobiony z resztek, ale i tak wydaje się dość solidny. Może służyć do różnych celów. | D23: KM_LAKOMY_TABLE_CIRCULAR_PEASANT_01.3ds | E23: KM_LAKOMY_TABLE_CIRCULAR_PEASANT_01.3ds | F23: Deska z miękiego drewna | G23: 10 | H23: Gwoździe | I23: 1 | J23: Smoła | K23: 1 | L23: - | N23: - | P23: - | R23: - | T23: - | V23: - | X23: - | Z23: - | AB23: - | AD23: 5 | AE23: Vob | AF23: table | AG23: TRUE | AH23: TRUE | AI23: =IFERROR(VLOOKUP(F23,Cennik!$A$4:$B892, 2, FALSE()) * G23 + VLOOKUP(H23,Cennik!$A$4:$B892, 2, FALSE()) * I23 + VLOOKUP(J23,Cennik!$A$4:$B892, 2, FALSE()) * K23 + VLOOKUP(L23,Cennik!$A$4:$B892, 2, FALSE()) * M23 + VLOOKUP(N23,Cennik!$A$4:$B892, 2, FALSE()) * O23 + VLOOKUP(P23,Cennik!$A$4:$B892, 2, FALSE()) * Q23 + VLOOKUP(R23,Cennik!$A$4:$B892, 2, FALSE()) * S23 + VLOOKUP(T23,Cennik!$A$4:$B892, 2, FALSE()) * U23 + VLOOKUP(V23,Cennik!$A$4:$B892, 2, FALSE()) * W23 + VLOOKUP(X23,Cennik!$A$4:$B892, 2, FALSE()) * Y23 + VLOOKUP(Z23,Cennik!$A$4:$B892, 2, FALSE()) * AA23 + VLOOKUP(AB23,Cennik!$A$4:$B892, 2, FALSE() * AC23),"Brak wartości") -> Brak wartości
A24: Karczmienna ława | B24: 1 | C24: Ława zwykle stawiana w karczmach lub innych budach. | D24: KM_VOB_TAVERN_TABLE_01.3ds | E24: KM_VOB_TAVERN_TABLE_01.3ds | F24: Deska z miękiego drewna | G24: 10 | H24: Gwoździe | I24: 1 | J24: Smoła | K24: 1 | L24: - | N24: - | P24: - | R24: - | T24: - | V24: - | X24: - | Z24: - | AB24: - | AD24: 5 | AE24: Vob | AF24: table | AG24: TRUE | AH24: TRUE | AI24: =IFERROR(VLOOKUP(F24,Cennik!$A$4:$B892, 2, FALSE()) * G24 + VLOOKUP(H24,Cennik!$A$4:$B892, 2, FALSE()) * I24 + VLOOKUP(J24,Cennik!$A$4:$B892, 2, FALSE()) * K24 + VLOOKUP(L24,Cennik!$A$4:$B892, 2, FALSE()) * M24 + VLOOKUP(N24,Cennik!$A$4:$B892, 2, FALSE()) * O24 + VLOOKUP(P24,Cennik!$A$4:$B892, 2, FALSE()) * Q24 + VLOOKUP(R24,Cennik!$A$4:$B892, 2, FALSE()) * S24 + VLOOKUP(T24,Cennik!$A$4:$B892, 2, FALSE()) * U24 + VLOOKUP(V24,Cennik!$A$4:$B892, 2, FALSE()) * W24 + VLOOKUP(X24,Cennik!$A$4:$B892, 2, FALSE()) * Y24 + VLOOKUP(Z24,Cennik!$A$4:$B892, 2, FALSE()) * AA24 + VLOOKUP(AB24,Cennik!$A$4:$B892, 2, FALSE() * AC24),"Brak wartości") -> Brak wartości
A25: Bukowy stół | B25: 2 | C25: Ten mebel bukowy to najlepszy wybór dla każdego, kto ceni sobie solidność i prostotę. | D25: GS_CITY_TABLE_NORMAL_BLACK_01_KOZA.3ds | E25: GS_CITY_TABLE_NORMAL_BLACK_01_KOZA.3ds | F25: Deska z twardego drewna | G25: 10 | H25: Deska z miękiego drewna | I25: 6 | J25: Gwoździe | K25: 2 | L25: Smoła | M25: 1 | N25: - | P25: - | R25: - | T25: - | V25: - | X25: - | Z25: - | AB25: - | AD25: 15 | AE25: Vob | AF25: table | AG25: TRUE | AH25: TRUE | AI25: =IFERROR(VLOOKUP(F25,Cennik!$A$4:$B892, 2, FALSE()) * G25 + VLOOKUP(H25,Cennik!$A$4:$B892, 2, FALSE()) * I25 + VLOOKUP(J25,Cennik!$A$4:$B892, 2, FALSE()) * K25 + VLOOKUP(L25,Cennik!$A$4:$B892, 2, FALSE()) * M25 + VLOOKUP(N25,Cennik!$A$4:$B892, 2, FALSE()) * O25 + VLOOKUP(P25,Cennik!$A$4:$B892, 2, FALSE()) * Q25 + VLOOKUP(R25,Cennik!$A$4:$B892, 2, FALSE()) * S25 + VLOOKUP(T25,Cennik!$A$4:$B892, 2, FALSE()) * U25 + VLOOKUP(V25,Cennik!$A$4:$B892, 2, FALSE()) * W25 + VLOOKUP(X25,Cennik!$A$4:$B892, 2, FALSE()) * Y25 + VLOOKUP(Z25,Cennik!$A$4:$B892, 2, FALSE()) * AA25 + VLOOKUP(AB25,Cennik!$A$4:$B892, 2, FALSE() * AC25),"Brak wartości") -> Brak wartości
A26: Bukowy stół 2 | B26: 2 | C26: Ten mebel bukowy to najlepszy wybór dla każdego, kto ceni sobie solidność i prostotę. | D26: GS_LOB_TABLE_HEAVY_BLACK_01_KOZA.3ds | E26: GS_LOB_TABLE_HEAVY_BLACK_01_KOZA.3ds | F26: Deska z twardego drewna | G26: 10 | H26: Deska z miękiego drewna | I26: 6 | J26: Gwoździe | K26: 2 | L26: Smoła | M26: 1 | N26: - | P26: - | R26: - | T26: - | V26: - | X26: - | Z26: - | AB26: - | AD26: 15 | AE26: Vob | AF26: table | AG26: TRUE | AH26: TRUE | AI26: =IFERROR(VLOOKUP(F26,Cennik!$A$4:$B892, 2, FALSE()) * G26 + VLOOKUP(H26,Cennik!$A$4:$B892, 2, FALSE()) * I26 + VLOOKUP(J26,Cennik!$A$4:$B892, 2, FALSE()) * K26 + VLOOKUP(L26,Cennik!$A$4:$B892, 2, FALSE()) * M26 + VLOOKUP(N26,Cennik!$A$4:$B892, 2, FALSE()) * O26 + VLOOKUP(P26,Cennik!$A$4:$B892, 2, FALSE()) * Q26 + VLOOKUP(R26,Cennik!$A$4:$B892, 2, FALSE()) * S26 + VLOOKUP(T26,Cennik!$A$4:$B892, 2, FALSE()) * U26 + VLOOKUP(V26,Cennik!$A$4:$B892, 2, FALSE()) * W26 + VLOOKUP(X26,Cennik!$A$4:$B892, 2, FALSE()) * Y26 + VLOOKUP(Z26,Cennik!$A$4:$B892, 2, FALSE()) * AA26 + VLOOKUP(AB26,Cennik!$A$4:$B892, 2, FALSE() * AC26),"Brak wartości") -> Brak wartości
A27: Bukowy okrągły stół | B27: 2 | C27: Ten mebel bukowy to najlepszy wybór dla każdego, kto ceni sobie solidność i prostotę. | D27: GS_TABLE_CIRCULAR_BLACK_01_KOZA.3ds | E27: GS_TABLE_CIRCULAR_BLACK_01_KOZA.3ds | F27: Deska z twardego drewna | G27: 10 | H27: Deska z miękiego drewna | I27: 6 | J27: Gwoździe | K27: 2 | L27: Smoła | M27: 1 | N27: - | P27: - | R27: - | T27: - | V27: - | X27: - | Z27: - | AB27: - | AD27: 15 | AE27: Vob | AF27: table | AG27: TRUE | AH27: TRUE | AI27: =IFERROR(VLOOKUP(F27,Cennik!$A$4:$B892, 2, FALSE()) * G27 + VLOOKUP(H27,Cennik!$A$4:$B892, 2, FALSE()) * I27 + VLOOKUP(J27,Cennik!$A$4:$B892, 2, FALSE()) * K27 + VLOOKUP(L27,Cennik!$A$4:$B892, 2, FALSE()) * M27 + VLOOKUP(N27,Cennik!$A$4:$B892, 2, FALSE()) * O27 + VLOOKUP(P27,Cennik!$A$4:$B892, 2, FALSE()) * Q27 + VLOOKUP(R27,Cennik!$A$4:$B892, 2, FALSE()) * S27 + VLOOKUP(T27,Cennik!$A$4:$B892, 2, FALSE()) * U27 + VLOOKUP(V27,Cennik!$A$4:$B892, 2, FALSE()) * W27 + VLOOKUP(X27,Cennik!$A$4:$B892, 2, FALSE()) * Y27 + VLOOKUP(Z27,Cennik!$A$4:$B892, 2, FALSE()) * AA27 + VLOOKUP(AB27,Cennik!$A$4:$B892, 2, FALSE() * AC27),"Brak wartości") -> Brak wartości
A28: Długi bukowy stół | B28: 2 | C28: Ten mebel bukowy to najlepszy wybór dla każdego, kto ceni sobie solidność i prostotę. | D28: GS_LOB_TABLE_HEAVY_LONG_BLACK_01_KOZA.3ds | E28: GS_LOB_TABLE_HEAVY_LONG_BLACK_01_KOZA.3ds | F28: Deska z twardego drewna | G28: 10 | H28: Deska z miękiego drewna | I28: 6 | J28: Gwoździe | K28: 2 | L28: Smoła | M28: 1 | N28: - | P28: - | R28: - | T28: - | V28: - | X28: - | Z28: - | AB28: - | AD28: 15 | AE28: Vob | AF28: table | AG28: TRUE | AH28: TRUE | AI28: =IFERROR(VLOOKUP(F28,Cennik!$A$4:$B892, 2, FALSE()) * G28 + VLOOKUP(H28,Cennik!$A$4:$B892, 2, FALSE()) * I28 + VLOOKUP(J28,Cennik!$A$4:$B892, 2, FALSE()) * K28 + VLOOKUP(L28,Cennik!$A$4:$B892, 2, FALSE()) * M28 + VLOOKUP(N28,Cennik!$A$4:$B892, 2, FALSE()) * O28 + VLOOKUP(P28,Cennik!$A$4:$B892, 2, FALSE()) * Q28 + VLOOKUP(R28,Cennik!$A$4:$B892, 2, FALSE()) * S28 + VLOOKUP(T28,Cennik!$A$4:$B892, 2, FALSE()) * U28 + VLOOKUP(V28,Cennik!$A$4:$B892, 2, FALSE()) * W28 + VLOOKUP(X28,Cennik!$A$4:$B892, 2, FALSE()) * Y28 + VLOOKUP(Z28,Cennik!$A$4:$B892, 2, FALSE()) * AA28 + VLOOKUP(AB28,Cennik!$A$4:$B892, 2, FALSE() * AC28),"Brak wartości") -> Brak wartości
A29: Bukowy stolik z półkami | B29: 2 | C29: Ten mebel bukowy to najlepszy wybór dla każdego, kto ceni sobie solidność i prostotę. | D29: GS_VOB_TABLESHELVES_BLACK_01_KOZA.3ds | E29: GS_VOB_TABLESHELVES_BLACK_01_KOZA.3ds | F29: Deska z twardego drewna | G29: 10 | H29: Deska z miękiego drewna | I29: 6 | J29: Gwoździe | K29: 2 | L29: Smoła | M29: 1 | N29: - | P29: - | R29: - | T29: - | V29: - | X29: - | Z29: - | AB29: - | AD29: 15 | AE29: Vob | AF29: table | AG29: TRUE | AH29: TRUE | AI29: =IFERROR(VLOOKUP(F29,Cennik!$A$4:$B892, 2, FALSE()) * G29 + VLOOKUP(H29,Cennik!$A$4:$B892, 2, FALSE()) * I29 + VLOOKUP(J29,Cennik!$A$4:$B892, 2, FALSE()) * K29 + VLOOKUP(L29,Cennik!$A$4:$B892, 2, FALSE()) * M29 + VLOOKUP(N29,Cennik!$A$4:$B892, 2, FALSE()) * O29 + VLOOKUP(P29,Cennik!$A$4:$B892, 2, FALSE()) * Q29 + VLOOKUP(R29,Cennik!$A$4:$B892, 2, FALSE()) * S29 + VLOOKUP(T29,Cennik!$A$4:$B892, 2, FALSE()) * U29 + VLOOKUP(V29,Cennik!$A$4:$B892, 2, FALSE()) * W29 + VLOOKUP(X29,Cennik!$A$4:$B892, 2, FALSE()) * Y29 + VLOOKUP(Z29,Cennik!$A$4:$B892, 2, FALSE()) * AA29 + VLOOKUP(AB29,Cennik!$A$4:$B892, 2, FALSE() * AC29),"Brak wartości") -> Brak wartości
A30: Okrągły stolik | B30: 2 | C30: Stolik zwykle stawiany w karczmach lub innych budach. | D30: DT_TABLE_01.3ds | E30: DT_TABLE_01.3ds | F30: Deska z twardego drewna | G30: 10 | H30: Deska z miękiego drewna | I30: 6 | J30: Gwoździe | K30: 2 | L30: Smoła | M30: 1 | N30: - | P30: - | R30: - | T30: - | V30: - | X30: - | Z30: - | AB30: - | AD30: 15 | AE30: Vob | AF30: table | AG30: TRUE | AH30: TRUE | AI30: =IFERROR(VLOOKUP(F30,Cennik!$A$4:$B892, 2, FALSE()) * G30 + VLOOKUP(H30,Cennik!$A$4:$B892, 2, FALSE()) * I30 + VLOOKUP(J30,Cennik!$A$4:$B892, 2, FALSE()) * K30 + VLOOKUP(L30,Cennik!$A$4:$B892, 2, FALSE()) * M30 + VLOOKUP(N30,Cennik!$A$4:$B892, 2, FALSE()) * O30 + VLOOKUP(P30,Cennik!$A$4:$B892, 2, FALSE()) * Q30 + VLOOKUP(R30,Cennik!$A$4:$B892, 2, FALSE()) * S30 + VLOOKUP(T30,Cennik!$A$4:$B892, 2, FALSE()) * U30 + VLOOKUP(V30,Cennik!$A$4:$B892, 2, FALSE()) * W30 + VLOOKUP(X30,Cennik!$A$4:$B892, 2, FALSE()) * Y30 + VLOOKUP(Z30,Cennik!$A$4:$B892, 2, FALSE()) * AA30 + VLOOKUP(AB30,Cennik!$A$4:$B892, 2, FALSE() * AC30),"Brak wartości") -> Brak wartości
A31: Prosty stół | B31: 2 | C31: Nieoceniony w swojej prostocie, służy nie tylko do spożywania posiłków, ale również jako miejsce pracy czy zabawy. | D31: OC_TABLE_V1.3ds | E31: OC_TABLE_V1.3ds | F31: Deska z twardego drewna | G31: 10 | H31: Deska z miękiego drewna | I31: 6 | J31: Gwoździe | K31: 2 | L31: Smoła | M31: 1 | N31: - | P31: - | R31: - | T31: - | V31: - | X31: - | Z31: - | AB31: - | AD31: 15 | AE31: Vob | AF31: table | AG31: TRUE | AH31: TRUE | AI31: =IFERROR(VLOOKUP(F31,Cennik!$A$4:$B892, 2, FALSE()) * G31 + VLOOKUP(H31,Cennik!$A$4:$B892, 2, FALSE()) * I31 + VLOOKUP(J31,Cennik!$A$4:$B892, 2, FALSE()) * K31 + VLOOKUP(L31,Cennik!$A$4:$B892, 2, FALSE()) * M31 + VLOOKUP(N31,Cennik!$A$4:$B892, 2, FALSE()) * O31 + VLOOKUP(P31,Cennik!$A$4:$B892, 2, FALSE()) * Q31 + VLOOKUP(R31,Cennik!$A$4:$B892, 2, FALSE()) * S31 + VLOOKUP(T31,Cennik!$A$4:$B892, 2, FALSE()) * U31 + VLOOKUP(V31,Cennik!$A$4:$B892, 2, FALSE()) * W31 + VLOOKUP(X31,Cennik!$A$4:$B892, 2, FALSE()) * Y31 + VLOOKUP(Z31,Cennik!$A$4:$B892, 2, FALSE()) * AA31 + VLOOKUP(AB31,Cennik!$A$4:$B892, 2, FALSE() * AC31),"Brak wartości") -> Brak wartości
A32: Długa ława | B32: 2 | C32: Nieoceniony w swojej prostocie, służy nie tylko do spożywania posiłków, ale również jako miejsce pracy czy zabawy. | D32: KM_VOB_MERCHANT_LONGTABLE.3ds | E32: KM_VOB_MERCHANT_LONGTABLE.3ds | F32: Deska z twardego drewna | G32: 10 | H32: Deska z miękiego drewna | I32: 6 | J32: Gwoździe | K32: 2 | L32: Smoła | M32: 1 | N32: - | P32: - | R32: - | T32: - | V32: - | X32: - | Z32: - | AB32: - | AD32: 15 | AE32: Vob | AF32: table | AG32: TRUE | AH32: TRUE | AI32: =IFERROR(VLOOKUP(F32,Cennik!$A$4:$B892, 2, FALSE()) * G32 + VLOOKUP(H32,Cennik!$A$4:$B892, 2, FALSE()) * I32 + VLOOKUP(J32,Cennik!$A$4:$B892, 2, FALSE()) * K32 + VLOOKUP(L32,Cennik!$A$4:$B892, 2, FALSE()) * M32 + VLOOKUP(N32,Cennik!$A$4:$B892, 2, FALSE()) * O32 + VLOOKUP(P32,Cennik!$A$4:$B892, 2, FALSE()) * Q32 + VLOOKUP(R32,Cennik!$A$4:$B892, 2, FALSE()) * S32 + VLOOKUP(T32,Cennik!$A$4:$B892, 2, FALSE()) * U32 + VLOOKUP(V32,Cennik!$A$4:$B892, 2, FALSE()) * W32 + VLOOKUP(X32,Cennik!$A$4:$B892, 2, FALSE()) * Y32 + VLOOKUP(Z32,Cennik!$A$4:$B892, 2, FALSE()) * AA32 + VLOOKUP(AB32,Cennik!$A$4:$B892, 2, FALSE() * AC32),"Brak wartości") -> Brak wartości
A33: Dębowy stół | B33: 3 | C33: Ten stół dębowy to najlepszy wybór dla każdego, kto ceni sobie solidność i prostotę. | D33: GS_CITY_TABLE_NORMAL_BROWN_01_KOZA.3ds | E33: GS_CITY_TABLE_NORMAL_BROWN_01_KOZA.3ds | F33: Deska z szlachetnego drewna | G33: 10 | H33: Twarde drewno | I33: 2 | J33: Gwoździe | K33: 3 | L33: Smoła | M33: 1 | N33: - | P33: - | R33: - | T33: - | V33: - | X33: - | Z33: - | AB33: - | AD33: 25 | AE33: Vob | AF33: table | AG33: TRUE | AH33: TRUE | AI33: =IFERROR(VLOOKUP(F33,Cennik!$A$4:$B892, 2, FALSE()) * G33 + VLOOKUP(H33,Cennik!$A$4:$B892, 2, FALSE()) * I33 + VLOOKUP(J33,Cennik!$A$4:$B892, 2, FALSE()) * K33 + VLOOKUP(L33,Cennik!$A$4:$B892, 2, FALSE()) * M33 + VLOOKUP(N33,Cennik!$A$4:$B892, 2, FALSE()) * O33 + VLOOKUP(P33,Cennik!$A$4:$B892, 2, FALSE()) * Q33 + VLOOKUP(R33,Cennik!$A$4:$B892, 2, FALSE()) * S33 + VLOOKUP(T33,Cennik!$A$4:$B892, 2, FALSE()) * U33 + VLOOKUP(V33,Cennik!$A$4:$B892, 2, FALSE()) * W33 + VLOOKUP(X33,Cennik!$A$4:$B892, 2, FALSE()) * Y33 + VLOOKUP(Z33,Cennik!$A$4:$B892, 2, FALSE()) * AA33 + VLOOKUP(AB33,Cennik!$A$4:$B892, 2, FALSE() * AC33),"Brak wartości") -> Brak wartości
A34: Dębowy stół 2 | B34: 3 | C34: Ten stół dębowy to najlepszy wybór dla każdego, kto ceni sobie solidność i prostotę. | D34: GS_LOB_TABLE_HEAVY_BROWN_01_KOZA.3ds | E34: GS_LOB_TABLE_HEAVY_BROWN_01_KOZA.3ds | F34: Deska z szlachetnego drewna | G34: 10 | H34: Twarde drewno | I34: 2 | J34: Gwoździe | K34: 3 | L34: Smoła | M34: 1 | N34: - | P34: - | R34: - | T34: - | V34: - | X34: - | Z34: - | AB34: - | AD34: 25 | AE34: Vob | AF34: table | AG34: TRUE | AH34: TRUE | AI34: =IFERROR(VLOOKUP(F34,Cennik!$A$4:$B892, 2, FALSE()) * G34 + VLOOKUP(H34,Cennik!$A$4:$B892, 2, FALSE()) * I34 + VLOOKUP(J34,Cennik!$A$4:$B892, 2, FALSE()) * K34 + VLOOKUP(L34,Cennik!$A$4:$B892, 2, FALSE()) * M34 + VLOOKUP(N34,Cennik!$A$4:$B892, 2, FALSE()) * O34 + VLOOKUP(P34,Cennik!$A$4:$B892, 2, FALSE()) * Q34 + VLOOKUP(R34,Cennik!$A$4:$B892, 2, FALSE()) * S34 + VLOOKUP(T34,Cennik!$A$4:$B892, 2, FALSE()) * U34 + VLOOKUP(V34,Cennik!$A$4:$B892, 2, FALSE()) * W34 + VLOOKUP(X34,Cennik!$A$4:$B892, 2, FALSE()) * Y34 + VLOOKUP(Z34,Cennik!$A$4:$B892, 2, FALSE()) * AA34 + VLOOKUP(AB34,Cennik!$A$4:$B892, 2, FALSE() * AC34),"Brak wartości") -> Brak wartości
A35: Dębowy okrągły stół | B35: 3 | C35: Ten stół dębowy to najlepszy wybór dla każdego, kto ceni sobie solidność i prostotę. | D35: GS_TABLE_CIRCULAR_BROWN_01_KOZA.3ds | E35: GS_TABLE_CIRCULAR_BROWN_01_KOZA.3ds | F35: Deska z szlachetnego drewna | G35: 10 | H35: Twarde drewno | I35: 2 | J35: Gwoździe | K35: 3 | L35: Smoła | M35: 1 | N35: - | P35: - | R35: - | T35: - | V35: - | X35: - | Z35: - | AB35: - | AD35: 25 | AE35: Vob | AF35: table | AG35: TRUE | AH35: TRUE | AI35: =IFERROR(VLOOKUP(F35,Cennik!$A$4:$B892, 2, FALSE()) * G35 + VLOOKUP(H35,Cennik!$A$4:$B892, 2, FALSE()) * I35 + VLOOKUP(J35,Cennik!$A$4:$B892, 2, FALSE()) * K35 + VLOOKUP(L35,Cennik!$A$4:$B892, 2, FALSE()) * M35 + VLOOKUP(N35,Cennik!$A$4:$B892, 2, FALSE()) * O35 + VLOOKUP(P35,Cennik!$A$4:$B892, 2, FALSE()) * Q35 + VLOOKUP(R35,Cennik!$A$4:$B892, 2, FALSE()) * S35 + VLOOKUP(T35,Cennik!$A$4:$B892, 2, FALSE()) * U35 + VLOOKUP(V35,Cennik!$A$4:$B892, 2, FALSE()) * W35 + VLOOKUP(X35,Cennik!$A$4:$B892, 2, FALSE()) * Y35 + VLOOKUP(Z35,Cennik!$A$4:$B892, 2, FALSE()) * AA35 + VLOOKUP(AB35,Cennik!$A$4:$B892, 2, FALSE() * AC35),"Brak wartości") -> Brak wartości
